<?xml version="1.0" encoding="utf-8"?>
<!-- This URDF was automatically created by SolidWorks to URDF Exporter! Originally created by Stephen Brawner (brawner@gmail.com) 
     Commit Version: 1.6.0-4-g7f85cfe  Build Version: 1.6.7995.38578
     For more information, please see http://wiki.ros.org/sw_urdf_exporter -->
<robot
  name="Hexapod">
  <link
    name="base_link">
    <inertial>
      <origin
        xyz="-6.18193581229152E-06 2.39717543056817E-06 0.0161961871063663"
        rpy="0 0 0" />
      <mass
        value="0.786295694888978" />
      <inertia
        ixx="0.00078778573537143"
        ixy="8.85654590300931E-09"
        ixz="2.40443432739839E-08"
        iyy="0.00086497615387617"
        iyz="1.37840846691492E-08"
        izz="0.00156986494830974" />
    </inertial>
    <visual>
      <origin
        xyz="0 0 0"
        rpy="0 0 0" />
      <geometry>
        <mesh
          filename="package://robot_description/meshes/base_link.STL" />
      </geometry>
      <material
        name="">
        <color
          rgba="1 1 1 1" />
      </material>
    </visual>
    <collision>
      <origin
        xyz="0 0 0"
        rpy="0 0 0" />
      <geometry>
        <mesh
          filename="package://robot_description/meshes/base_link.STL" />
      </geometry>
    </collision>
  </link>
  <link
    name="front_left_coxa_link">
    <inertial>
      <origin
        xyz="0.042272 0.041896 0.00059547"
        rpy="0 0 0" />
      <mass
        value="0.086281" />
      <inertia
        ixx="2.3604E-05"
        ixy="-2.2438E-06"
        ixz="-1.3482E-07"
        iyy="2.3608E-05"
        iyz="-9.0884E-08"
        izz="1.6384E-05" />
    </inertial>
    <visual>
      <origin
        xyz="0 0 0"
        rpy="0 0 0" />
      <geometry>
        <mesh
          filename="package://robot_description/meshes/front_left_coxa_link.STL" />
      </geometry>
      <material
        name="">
        <color
          rgba="1 1 1 1" />
      </material>
    </visual>
    <collision>
      <origin
        xyz="0 0 0"
        rpy="0 0 0" />
      <geometry>
        <mesh
          filename="package://robot_description/meshes/front_left_coxa_link.STL" />
      </geometry>
    </collision>
  </link>
  <joint
    name="front_left_coxa_joint"
    type="revolute">
    <origin
      xyz="0.0597794623037307 0.0610074569827942 0.0154258000000004"
      rpy="0 0 0" />
    <parent
      link="base_link" />
    <child
      link="front_left_coxa_link" />
    <axis
      xyz="0.0425207281634428 0.00387756005096805 -0.999088060285229" />
    <limit
      lower="-1.57"
      upper="1.57"
      effort="0"
      velocity="0" />
  </joint>
  <link
    name="front_left_femur_link">
    <inertial>
      <origin
        xyz="0.052841 0.0010893 -0.0016863"
        rpy="0 0 0" />
      <mass
        value="0.0314" />
      <inertia
        ixx="3.499E-06"
        ixy="-2.5485E-09"
        ixz="4.2611E-07"
        iyy="3.7915E-05"
        iyz="4.9086E-08"
        izz="3.7503E-05" />
    </inertial>
    <visual>
      <origin
        xyz="0 0 0"
        rpy="0 0 0" />
      <geometry>
        <mesh
          filename="package://robot_description/meshes/front_left_femur_link.STL" />
      </geometry>
      <material
        name="">
        <color
          rgba="1 1 1 1" />
      </material>
    </visual>
    <collision>
      <origin
        xyz="0 0 0"
        rpy="0 0 0" />
      <geometry>
        <mesh
          filename="package://robot_description/meshes/front_left_femur_link.STL" />
      </geometry>
    </collision>
  </link>
  <joint
    name="front_left_femur_joint"
    type="revolute">
    <origin
      xyz="0.0506354195835637 0.0493770568562628 0.0103729999999975"
      rpy="-0.000104123938980253 0.000104107183134694 0.785317693150283" />
    <parent
      link="front_left_coxa_link" />
    <child
      link="front_left_femur_link" />
    <axis
      xyz="0 1 0" />
    <limit
      lower="-1.57"
      upper="1.57"
      effort="0"
      velocity="0" />
  </joint>
  <link
    name="front_left_tibia_link">
    <inertial>
      <origin
        xyz="-0.036753 0.00043104 0.0037586"
        rpy="0 0 0" />
      <mass
        value="0.095402" />
      <inertia
        ixx="1.6965E-05"
        ixy="2.6445E-08"
        ixz="1.0538E-05"
        iyy="8.8702E-05"
        iyz="-2.2918E-10"
        izz="8.2071E-05" />
    </inertial>
    <visual>
      <origin
        xyz="0 0 0"
        rpy="0 0 0" />
      <geometry>
        <mesh
          filename="package://robot_description/meshes/front_left_tibia_link.STL" />
      </geometry>
      <material
        name="">
        <color
          rgba="1 1 1 1" />
      </material>
    </visual>
    <collision>
      <origin
        xyz="0 0 0"
        rpy="0 0 0" />
      <geometry>
        <mesh
          filename="package://robot_description/meshes/front_left_tibia_link.STL" />
      </geometry>
    </collision>
  </link>
  <joint
    name="front_left_tibia_joint"
    type="revolute">
    <origin
      xyz="0.108492266657861 0 -0.00133055426669743"
      rpy="0.000184555914276492 -0.000184623471871961 0.00026345026142038" />
    <parent
      link="front_left_femur_link" />
    <child
      link="front_left_tibia_link" />
    <axis
      xyz="0 -1 0" />
    <limit
      lower="0"
      upper="3.1415"
      effort="0"
      velocity="0" />
  </joint>
  <link
    name="front_left_foot_link">
    <inertial>
      <origin
        xyz="1.14070369122699E-09 -1.1370719643633E-10 -0.000139135605409638"
        rpy="0 0 0" />
      <mass
        value="0.00102687106652255" />
      <inertia
        ixx="1.66564317116379E-08"
        ixy="6.03331683107328E-15"
        ixz="-5.74075577541418E-15"
        iyy="1.66564916079342E-08"
        iyz="5.72511609703753E-16"
        izz="1.7246104627114E-08" />
    </inertial>
    <visual>
      <origin
        xyz="0 0 0"
        rpy="0 0 0" />
      <geometry>
        <mesh
          filename="package://robot_description/meshes/front_left_foot_link.STL" />
      </geometry>
      <material
        name="">
        <color
          rgba="1 1 1 1" />
      </material>
    </visual>
    <collision>
      <origin
        xyz="0 0 0"
        rpy="0 0 0" />
      <geometry>
        <mesh
          filename="package://robot_description/meshes/front_left_foot_link.STL" />
      </geometry>
    </collision>
  </link>
  <joint
    name="front_left_foot_joint"
    type="fixed">
    <origin
      xyz="-0.157028654923345 -0.000166190898608631 0.0381859537813213"
      rpy="-2.271181641943 -0.422454157208771 -1.23828061902425" />
    <parent
      link="front_left_tibia_link" />
    <child
      link="front_left_foot_link" />
    <axis
      xyz="0 0 0" />
  </joint>
  <link
    name="middle_left_coxa_link">
    <inertial>
      <origin
        xyz="-0.00060292 0.05847 0.00059547"
        rpy="0 0 0" />
      <mass
        value="0.086281" />
      <inertia
        ixx="2.585E-05"
        ixy="-2.0825E-09"
        ixz="-3.1068E-08"
        iyy="2.1362E-05"
        iyz="-1.596E-07"
        izz="1.6384E-05" />
    </inertial>
    <visual>
      <origin
        xyz="0 0 0"
        rpy="0 0 0" />
      <geometry>
        <mesh
          filename="package://robot_description/meshes/middle_left_coxa_link.STL" />
      </geometry>
      <material
        name="">
        <color
          rgba="1 1 1 1" />
      </material>
    </visual>
    <collision>
      <origin
        xyz="0 0 0"
        rpy="0 0 0" />
      <geometry>
        <mesh
          filename="package://robot_description/meshes/middle_left_coxa_link.STL" />
      </geometry>
    </collision>
  </link>
  <joint
    name="middle_left_coxa_joint"
    type="revolute">
    <origin
      xyz="0 0.0864545384187688 0.0154258000000007"
      rpy="0 0 0" />
    <parent
      link="base_link" />
    <child
      link="middle_left_coxa_link" />
    <axis
      xyz="-8.04594058439077E-05 -0.000183005707343813 -0.999999980017597" />
    <limit
      lower="-1.57"
      upper="1.57"
      effort="0"
      velocity="0" />
  </joint>
  <link
    name="middle_left_femur_link">
    <inertial>
      <origin
        xyz="-0.0051763 0.00052888 -0.052845"
        rpy="0 0 0" />
      <mass
        value="0.0314" />
      <inertia
        ixx="3.7498E-05"
        ixy="3.6609E-09"
        ixz="-3.9522E-07"
        iyy="3.7921E-05"
        iyz="-4.3167E-08"
        izz="3.4983E-06" />
    </inertial>
    <visual>
      <origin
        xyz="0 0 0"
        rpy="0 0 0" />
      <geometry>
        <mesh
          filename="package://robot_description/meshes/middle_left_femur_link.STL" />
      </geometry>
      <material
        name="">
        <color
          rgba="1 1 1 1" />
      </material>
    </visual>
    <collision>
      <origin
        xyz="0 0 0"
        rpy="0 0 0" />
      <geometry>
        <mesh
          filename="package://robot_description/meshes/middle_left_femur_link.STL" />
      </geometry>
    </collision>
  </link>
  <joint
    name="middle_left_femur_joint"
    type="revolute">
    <origin
      xyz="2.10046607146265E-05 0.0696742115812287 0.0138198356843305"
      rpy="1.56394087721752 -1.46256545726282 0.00681533790492595" />
    <parent
      link="middle_left_coxa_link" />
    <child
      link="middle_left_femur_link" />
    <axis
      xyz="0 1 0" />
    <limit
      lower="-1.57"
      upper="1.57"
      effort="0"
      velocity="0" />
  </joint>
  <link
    name="middle_left_tibia_link">
    <inertial>
      <origin
        xyz="0.035157 0.00043104 0.011354"
        rpy="0 0 0" />
      <mass
        value="0.095402" />
      <inertia
        ixx="1.9749E-05"
        ixy="-2.4298E-08"
        ixz="-1.6869E-05"
        iyy="8.8702E-05"
        iyz="-1.0435E-08"
        izz="7.9287E-05" />
    </inertial>
    <visual>
      <origin
        xyz="0 0 0"
        rpy="0 0 0" />
      <geometry>
        <mesh
          filename="package://robot_description/meshes/middle_left_tibia_link.STL" />
      </geometry>
      <material
        name="">
        <color
          rgba="1 1 1 1" />
      </material>
    </visual>
    <collision>
      <origin
        xyz="0 0 0"
        rpy="0 0 0" />
      <geometry>
        <mesh
          filename="package://robot_description/meshes/middle_left_tibia_link.STL" />
      </geometry>
    </collision>
  </link>
  <joint
    name="middle_left_tibia_joint"
    type="revolute">
    <origin
      xyz="-0.00465888477440595 -0.000506201381017687 -0.108495899458512"
      rpy="0.000455617198050646 -1.15731885852398 0.107730800271824" />
    <parent
      link="middle_left_femur_link" />
    <child
      link="middle_left_tibia_link" />
    <axis
      xyz="0 -1 0" />
    <limit
      lower="0"
      upper="3.1415"
      effort="0"
      velocity="0" />
  </joint>
  <link
    name="middle_left_foot_link">
    <inertial>
      <origin
        xyz="8.33134791868419E-10 -7.87396869927903E-10 -0.000139135605393956"
        rpy="0 0 0" />
      <mass
        value="0.00102687106652256" />
      <inertia
        ixx="1.66564599387321E-08"
        ixy="3.05013189903406E-14"
        ixz="-4.19279946946903E-15"
        iyy="1.66564633808401E-08"
        iyz="3.9628877150851E-15"
        izz="1.7246104627114E-08" />
    </inertial>
    <visual>
      <origin
        xyz="0 0 0"
        rpy="0 0 0" />
      <geometry>
        <mesh
          filename="package://robot_description/meshes/middle_left_foot_link.STL" />
      </geometry>
      <material
        name="">
        <color
          rgba="1 1 1 1" />
      </material>
    </visual>
    <collision>
      <origin
        xyz="0 0 0"
        rpy="0 0 0" />
      <geometry>
        <mesh
          filename="package://robot_description/meshes/middle_left_foot_link.STL" />
      </geometry>
    </collision>
  </link>
  <joint
    name="middle_left_foot_joint"
    type="fixed">
    <origin
      xyz="0.15911554000758 -0.000166190898614748 0.0282561579362873"
      rpy="1.35669573662495 0 -1.57059641480066" />
    <parent
      link="middle_left_tibia_link" />
    <child
      link="middle_left_foot_link" />
    <axis
      xyz="0 0 0" />
  </joint>
  <link
    name="rear_left_coxa_link">
    <inertial>
      <origin
        xyz="-0.04032 0.043236 0.00059549"
        rpy="0 0 0" />
      <mass
        value="0.086281" />
      <inertia
        ixx="2.3608E-05"
        ixy="2.2438E-06"
        ixz="9.0883E-08"
        iyy="2.3604E-05"
        iyz="-1.3482E-07"
        izz="1.6384E-05" />
    </inertial>
    <visual>
      <origin
        xyz="0 0 0"
        rpy="0 0 0" />
      <geometry>
        <mesh
          filename="package://robot_description/meshes/rear_left_coxa_link.STL" />
      </geometry>
      <material
        name="">
        <color
          rgba="1 1 1 1" />
      </material>
    </visual>
    <collision>
      <origin
        xyz="0 0 0"
        rpy="0 0 0" />
      <geometry>
        <mesh
          filename="package://robot_description/meshes/rear_left_coxa_link.STL" />
      </geometry>
    </collision>
  </link>
  <joint
    name="rear_left_coxa_joint"
    type="revolute">
    <origin
      xyz="-0.0625828215626599 0.0588152120207696 0.0154258000000006"
      rpy="0 0 0" />
    <parent
      link="base_link" />
    <child
      link="rear_left_coxa_link" />
    <axis
      xyz="0 0 1" />
    <limit
      lower="-1.57"
      upper="1.57"
      effort="0"
      velocity="0" />
  </joint>
  <link
    name="rear_left_femur_link">
    <inertial>
      <origin
        xyz="0.053956 0.0016978 -0.0017331"
        rpy="0 0 0" />
      <mass
        value="0.030751" />
      <inertia
        ixx="3.4832E-06"
        ixy="-2.5371E-09"
        ixz="4.332E-07"
        iyy="3.7885E-05"
        iyz="4.9085E-08"
        izz="3.7487E-05" />
    </inertial>
    <visual>
      <origin
        xyz="0 0 0"
        rpy="0 0 0" />
      <geometry>
        <mesh
          filename="package://robot_description/meshes/rear_left_femur_link.STL" />
      </geometry>
      <material
        name="">
        <color
          rgba="1 1 1 1" />
      </material>
    </visual>
    <collision>
      <origin
        xyz="0 0 0"
        rpy="0 0 0" />
      <geometry>
        <mesh
          filename="package://robot_description/meshes/rear_left_femur_link.STL" />
      </geometry>
    </collision>
  </link>
  <joint
    name="rear_left_femur_joint"
    type="revolute">
    <origin
      xyz="-0.0478016922764079 0.0515996698665222 0.0103730000000015"
      rpy="-0.00010412393892102 -0.000104140694076206 2.35611404162862" />
    <parent
      link="rear_left_coxa_link" />
    <child
      link="rear_left_femur_link" />
    <axis
      xyz="0 -1 0" />
    <limit
      lower="-1.57"
      upper="1.57"
      effort="0"
      velocity="0" />
  </joint>
  <link
    name="rear_left_tibia_link">
    <inertial>
      <origin
        xyz="-0.036754 0.00043104 0.0037527"
        rpy="0 0 0" />
      <mass
        value="0.095402" />
      <inertia
        ixx="1.6961E-05"
        ixy="2.6446E-08"
        ixz="1.0527E-05"
        iyy="8.8702E-05"
        iyz="-2.242E-10"
        izz="8.2075E-05" />
    </inertial>
    <visual>
      <origin
        xyz="0 0 0"
        rpy="0 0 0" />
      <geometry>
        <mesh
          filename="package://robot_description/meshes/rear_left_tibia_link.STL" />
      </geometry>
      <material
        name="">
        <color
          rgba="1 1 1 1" />
      </material>
    </visual>
    <collision>
      <origin
        xyz="0 0 0"
        rpy="0 0 0" />
      <geometry>
        <mesh
          filename="package://robot_description/meshes/rear_left_tibia_link.STL" />
      </geometry>
    </collision>
  </link>
  <joint
    name="rear_left_tibia_joint"
    type="revolute">
    <origin
      xyz="0.108491987220254 0 -0.0013531475220351"
      rpy="0.000184610780237547 0.000184543218609282 0.000263479964488295" />
    <parent
      link="rear_left_femur_link" />
    <child
      link="rear_left_tibia_link" />
    <axis
      xyz="0 -1 0" />
    <limit
      lower="0"
      upper="3.1415"
      effort="0"
      velocity="0" />
  </joint>
  <link
    name="rear_left_foot_link">
    <inertial>
      <origin
        xyz="9.79572360726433E-10 -5.95212740206463E-10 -0.000139135605487437"
        rpy="0 0 0" />
      <mass
        value="0.00102687106652255" />
      <inertia
        ixx="1.66564475959389E-08"
        ixy="2.71201159844128E-14"
        ixz="-4.92983811976141E-15"
        iyy="1.66564757236332E-08"
        iyz="2.99678870383865E-15"
        izz="1.7246104627114E-08" />
    </inertial>
    <visual>
      <origin
        xyz="0 0 0"
        rpy="0 0 0" />
      <geometry>
        <mesh
          filename="package://robot_description/meshes/rear_left_foot_link.STL" />
      </geometry>
      <material
        name="">
        <color
          rgba="1 1 1 1" />
      </material>
    </visual>
    <collision>
      <origin
        xyz="0 0 0"
        rpy="0 0 0" />
      <geometry>
        <mesh
          filename="package://robot_description/meshes/rear_left_foot_link.STL" />
      </geometry>
    </collision>
  </link>
  <joint
    name="rear_left_foot_joint"
    type="fixed">
    <origin
      xyz="-0.157034797728908 -0.000166190898612381 0.0381606844208325"
      rpy="-2.1990344128274 -8.04446851697625E-05 -1.57097933897523" />
    <parent
      link="rear_left_tibia_link" />
    <child
      link="rear_left_foot_link" />
    <axis
      xyz="0 0 0" />
  </joint>
  <link
    name="front_right_coxa_link">
    <inertial>
      <origin
        xyz="0.04316 -0.041173 0.00059549"
        rpy="0 0 0" />
      <mass
        value="0.086281" />
      <inertia
        ixx="2.3608E-05"
        ixy="2.2438E-06"
        ixz="-9.0883E-08"
        iyy="2.3604E-05"
        iyz="1.3482E-07"
        izz="1.6384E-05" />
    </inertial>
    <visual>
      <origin
        xyz="0 0 0"
        rpy="0 0 0" />
      <geometry>
        <mesh
          filename="package://robot_description/meshes/front_right_coxa_link.STL" />
      </geometry>
      <material
        name="">
        <color
          rgba="1 1 1 1" />
      </material>
    </visual>
    <collision>
      <origin
        xyz="0 0 0"
        rpy="0 0 0" />
      <geometry>
        <mesh
          filename="package://robot_description/meshes/front_right_coxa_link.STL" />
      </geometry>
    </collision>
  </link>
  <joint
    name="front_right_coxa_joint"
    type="revolute">
    <origin
      xyz="0.0597479377257695 -0.0608728713812492 0.0154258000000012"
      rpy="0 0 0" />
    <parent
      link="base_link" />
    <child
      link="front_right_coxa_link" />
    <axis
      xyz="-0.0437385357924751 0.00789225955945658 0.999011838130949" />
    <limit
      lower="-1.57"
      upper="1.57"
      effort="0"
      velocity="0" />
  </joint>
  <link
    name="front_right_femur_link">
    <inertial>
      <origin
        xyz="0.053956 0.0016978 -0.0017331"
        rpy="0 0 0" />
      <mass
        value="0.030751" />
      <inertia
        ixx="3.4832E-06"
        ixy="-2.5371E-09"
        ixz="4.332E-07"
        iyy="3.7885E-05"
        iyz="4.9085E-08"
        izz="3.7487E-05" />
    </inertial>
    <visual>
      <origin
        xyz="0 0 0"
        rpy="0 0 0" />
      <geometry>
        <mesh
          filename="package://robot_description/meshes/front_right_femur_link.STL" />
      </geometry>
      <material
        name="">
        <color
          rgba="1 1 1 1" />
      </material>
    </visual>
    <collision>
      <origin
        xyz="0 0 0"
        rpy="0 0 0" />
      <geometry>
        <mesh
          filename="package://robot_description/meshes/front_right_femur_link.STL" />
      </geometry>
    </collision>
  </link>
  <joint
    name="front_right_femur_joint"
    type="revolute">
    <origin
      xyz="0.0506416297387538 -0.0495369568805863 0.0103729999999976"
      rpy="-0.000104123938883876 -0.000104140694039058 -0.785478611961186" />
    <parent
      link="front_right_coxa_link" />
    <child
      link="front_right_femur_link" />
    <axis
      xyz="0 -1 0" />
    <limit
      lower="-1.57"
      upper="1.57"
      effort="0"
      velocity="0" />
  </joint>
  <link
    name="front_right_tibia_link">
    <inertial>
      <origin
        xyz="-0.036754 0.00043104 0.0037527"
        rpy="0 0 0" />
      <mass
        value="0.095402" />
      <inertia
        ixx="1.6961E-05"
        ixy="2.6443E-08"
        ixz="1.0527E-05"
        iyy="8.8702E-05"
        iyz="-2.2432E-10"
        izz="8.2075E-05" />
    </inertial>
    <visual>
      <origin
        xyz="0 0 0"
        rpy="0 0 0" />
      <geometry>
        <mesh
          filename="package://robot_description/meshes/front_right_tibia_link.STL" />
      </geometry>
      <material
        name="">
        <color
          rgba="1 1 1 1" />
      </material>
    </visual>
    <collision>
      <origin
        xyz="0 0 0"
        rpy="0 0 0" />
      <geometry>
        <mesh
          filename="package://robot_description/meshes/front_right_tibia_link.STL" />
      </geometry>
    </collision>
  </link>
  <joint
    name="front_right_tibia_joint"
    type="revolute">
    <origin
      xyz="0.10849 0 -0.0013531"
      rpy="0.00018461 0.00018454 0.00026348" />
    <parent
      link="front_right_femur_link" />
    <child
      link="front_right_tibia_link" />
    <axis
      xyz="0 -1 0" />
    <limit
      lower="0"
      upper="3.1415"
      effort="0"
      velocity="0" />
  </joint>
  <link
    name="front_right_foot_link">
    <inertial>
      <origin
        xyz="-4.92431262433257E-10 1.03551793528833E-09 -0.000139135605653394"
        rpy="0 0 0" />
      <mass
        value="0.00102687106652255" />
      <inertia
        ixx="1.6656480938687E-08"
        ixy="2.36984486257665E-14"
        ixz="2.47787044655469E-15"
        iyy="1.66564423808852E-08"
        iyz="-5.21001001947976E-15"
        izz="1.7246104627114E-08" />
    </inertial>
    <visual>
      <origin
        xyz="0 0 0"
        rpy="0 0 0" />
      <geometry>
        <mesh
          filename="package://robot_description/meshes/front_right_foot_link.STL" />
      </geometry>
      <material
        name="">
        <color
          rgba="1 1 1 1" />
      </material>
    </visual>
    <collision>
      <origin
        xyz="0 0 0"
        rpy="0 0 0" />
      <geometry>
        <mesh
          filename="package://robot_description/meshes/front_right_foot_link.STL" />
      </geometry>
    </collision>
  </link>
  <joint
    name="front_right_foot_joint"
    type="fixed">
    <origin
      xyz="-0.157034797728908 -0.000166190898609997 0.0381606844208381"
      rpy="2.27095727607043 -0.422354608328963 1.23800658745024" />
    <parent
      link="front_right_tibia_link" />
    <child
      link="front_right_foot_link" />
    <axis
      xyz="0 0 0" />
    <limit
      lower="0"
      upper="0"
      effort="0"
      velocity="0" />
  </joint>
  <link
    name="middle_right_coxa_link">
    <inertial>
      <origin
        xyz="0.00060348 -0.058469 0.00059547"
        rpy="0 0 0" />
      <mass
        value="0.086281" />
      <inertia
        ixx="2.585E-05"
        ixy="-2.0811E-09"
        ixz="3.1068E-08"
        iyy="2.1362E-05"
        iyz="1.596E-07"
        izz="1.6384E-05" />
    </inertial>
    <visual>
      <origin
        xyz="0 0 0"
        rpy="0 0 0" />
      <geometry>
        <mesh
          filename="package://robot_description/meshes/middle_right_coxa_link.STL" />
      </geometry>
      <material
        name="">
        <color
          rgba="1 1 1 1" />
      </material>
    </visual>
    <collision>
      <origin
        xyz="0 0 0"
        rpy="0 0 0" />
      <geometry>
        <mesh
          filename="package://robot_description/meshes/middle_right_coxa_link.STL" />
      </geometry>
    </collision>
  </link>
  <joint
    name="middle_right_coxa_joint"
    type="revolute">
    <origin
      xyz="0 -0.0864558000013206 0.0154258000001641"
      rpy="0 0 0" />
    <parent
      link="base_link" />
    <child
      link="middle_right_coxa_link" />
    <axis
      xyz="-8.04591239439089E-05 -0.000183005730591605 0.999999980017616" />
    <limit
      lower="-1.57"
      upper="1.57"
      effort="0"
      velocity="0" />
  </joint>
  <link
    name="middle_right_femur_link">
    <inertial>
      <origin
        xyz="0.034359 0.0016978 0.041639"
        rpy="0 0 0" />
      <mass
        value="0.030751" />
      <inertia
        ixx="2.4358E-05"
        ixy="-4.0394E-08"
        ixz="-1.656E-05"
        iyy="3.7885E-05"
        iyz="2.8001E-08"
        izz="1.6612E-05" />
    </inertial>
    <visual>
      <origin
        xyz="0 0 0"
        rpy="0 0 0" />
      <geometry>
        <mesh
          filename="package://robot_description/meshes/middle_right_femur_link.STL" />
      </geometry>
      <material
        name="">
        <color
          rgba="1 1 1 1" />
      </material>
    </visual>
    <collision>
      <origin
        xyz="0 0 0"
        rpy="0 0 0" />
      <geometry>
        <mesh
          filename="package://robot_description/meshes/middle_right_femur_link.STL" />
      </geometry>
    </collision>
  </link>
  <joint
    name="middle_right_femur_joint"
    type="revolute">
    <origin
      xyz="-2.04500179069247E-05 -0.0696729499986796 0.0103729999998343"
      rpy="-0.00017029088670727 0.912907710407541 -1.57101153482602" />
    <parent
      link="middle_right_coxa_link" />
    <child
      link="middle_right_femur_link" />
    <axis
      xyz="0 1 0" />
    <limit
      lower="-1.57"
      upper="1.57"
      effort="0"
      velocity="0" />
  </joint>
  <link
    name="middle_right_tibia_link">
    <inertial>
      <origin
        xyz="0.035157 0.00043104 0.011354"
        rpy="0 0 0" />
      <mass
        value="0.095402" />
      <inertia
        ixx="1.9749E-05"
        ixy="-2.43E-08"
        ixz="-1.6869E-05"
        iyy="8.8702E-05"
        iyz="-1.0435E-08"
        izz="7.9287E-05" />
    </inertial>
    <visual>
      <origin
        xyz="0 0 0"
        rpy="0 0 0" />
      <geometry>
        <mesh
          filename="package://robot_description/meshes/middle_right_tibia_link.STL" />
      </geometry>
      <material
        name="">
        <color
          rgba="1 1 1 1" />
      </material>
    </visual>
    <collision>
      <origin
        xyz="0 0 0"
        rpy="0 0 0" />
      <geometry>
        <mesh
          filename="package://robot_description/meshes/middle_right_tibia_link.STL" />
      </geometry>
    </collision>
  </link>
  <joint
    name="middle_right_tibia_joint"
    type="revolute">
    <origin
      xyz="0.067399025687048 0 0.0850277227476781"
      rpy="-3.14148378102785 0.498689769885715 -3.14123342941393" />
    <parent
      link="middle_right_femur_link" />
    <child
      link="middle_right_tibia_link" />
    <axis
      xyz="0 -1 0" />
    <limit
      lower="0"
      upper="3.1415"
      effort="0"
      velocity="0" />
  </joint>
  <link
    name="middle_right_foot_link">
    <inertial>
      <origin
        xyz="-9.24882211046424E-10 6.77469705334666E-10 -0.000139135605643083"
        rpy="0 0 0" />
      <mass
        value="0.00102687106652256" />
      <inertia
        ixx="1.6656452436194E-08"
        ixy="2.91241795993467E-14"
        ixz="4.65473682962743E-15"
        iyy="1.66564708833781E-08"
        iyz="-3.4084412137988E-15"
        izz="1.7246104627114E-08" />
    </inertial>
    <visual>
      <origin
        xyz="0 0 0"
        rpy="0 0 0" />
      <geometry>
        <mesh
          filename="package://robot_description/meshes/middle_right_foot_link.STL" />
      </geometry>
      <material
        name="">
        <color
          rgba="1 1 1 1" />
      </material>
    </visual>
    <collision>
      <origin
        xyz="0 0 0"
        rpy="0 0 0" />
      <geometry>
        <mesh
          filename="package://robot_description/meshes/middle_right_foot_link.STL" />
      </geometry>
    </collision>
  </link>
  <joint
    name="middle_right_foot_joint"
    type="fixed">
    <origin
      xyz="0.159115539999232 -0.0001661908986167 0.0282561579833033"
      rpy="-1.35669573692048 0 1.57099623878914" />
    <parent
      link="middle_right_tibia_link" />
    <child
      link="middle_right_foot_link" />
    <axis
      xyz="0 0 0" />
  </joint>
  <link
    name="rear_right_coxa_link">
    <inertial>
      <origin
        xyz="-0.041056 -0.04304 0.00059547"
        rpy="0 0 0" />
      <mass
        value="0.086281" />
      <inertia
        ixx="2.3604E-05"
        ixy="-2.2438E-06"
        ixz="1.3482E-07"
        iyy="2.3608E-05"
        iyz="9.0884E-08"
        izz="1.6384E-05" />
    </inertial>
    <visual>
      <origin
        xyz="0 0 0"
        rpy="0 0 0" />
      <geometry>
        <mesh
          filename="package://robot_description/meshes/rear_right_coxa_link.STL" />
      </geometry>
      <material
        name="">
        <color
          rgba="1 1 1 1" />
      </material>
    </visual>
    <collision>
      <origin
        xyz="0 0 0"
        rpy="0 0 0" />
      <geometry>
        <mesh
          filename="package://robot_description/meshes/rear_right_coxa_link.STL" />
      </geometry>
    </collision>
  </link>
  <joint
    name="rear_right_coxa_joint"
    type="revolute">
    <origin
      xyz="-0.0609902962483643 -0.0598679792477214 0.0154257999999996"
      rpy="0 0 0" />
    <parent
      link="base_link" />
    <child
      link="rear_right_coxa_link" />
    <axis
      xyz="-0.00419160564654864 -0.0399618653751459 -0.999192413781171" />
    <limit
      lower="-1.57"
      upper="1.57"
      effort="0"
      velocity="0" />
  </joint>
  <link
    name="rear_right_femur_link">
    <inertial>
      <origin
        xyz="0.053957 0.0016978 -0.0017219"
        rpy="0 0 0" />
      <mass
        value="0.030751" />
      <inertia
        ixx="3.483E-06"
        ixy="-2.5473E-09"
        ixz="4.2611E-07"
        iyy="3.7885E-05"
        iyz="4.9084E-08"
        izz="3.7487E-05" />
    </inertial>
    <visual>
      <origin
        xyz="0 0 0"
        rpy="0 0 0" />
      <geometry>
        <mesh
          filename="package://robot_description/meshes/rear_right_femur_link.STL" />
      </geometry>
      <material
        name="">
        <color
          rgba="1 1 1 1" />
      </material>
    </visual>
    <collision>
      <origin
        xyz="0 0 0"
        rpy="0 0 0" />
      <geometry>
        <mesh
          filename="package://robot_description/meshes/rear_right_femur_link.STL" />
      </geometry>
    </collision>
  </link>
  <joint
    name="rear_right_femur_joint"
    type="revolute">
    <origin
      xyz="-0.049419532013472 -0.0505215882168034 0.0103730000000031"
      rpy="-0.000104123938777913 0.000104107182932361 -2.35627496043963" />
    <parent
      link="rear_right_coxa_link" />
    <child
      link="rear_right_femur_link" />
    <axis
      xyz="0 1 0" />
    <limit
      lower="-1.57"
      upper="1.57"
      effort="0"
      velocity="0" />
  </joint>
  <link
    name="rear_right_tibia_link">
    <inertial>
      <origin
        xyz="-0.036753 0.00043104 0.0037586"
        rpy="0 0 0" />
      <mass
        value="0.095402" />
      <inertia
        ixx="1.6965E-05"
        ixy="2.6445E-08"
        ixz="1.0538E-05"
        iyy="8.8702E-05"
        iyz="-2.2924E-10"
        izz="8.2071E-05" />
    </inertial>
    <visual>
      <origin
        xyz="0 0 0"
        rpy="0 0 0" />
      <geometry>
        <mesh
          filename="package://robot_description/meshes/rear_right_tibia_link.STL" />
      </geometry>
      <material
        name="">
        <color
          rgba="1 1 1 1" />
      </material>
    </visual>
    <collision>
      <origin
        xyz="0 0 0"
        rpy="0 0 0" />
      <geometry>
        <mesh
          filename="package://robot_description/meshes/rear_right_tibia_link.STL" />
      </geometry>
    </collision>
  </link>
  <joint
    name="rear_right_tibia_joint"
    type="revolute">
    <origin
      xyz="0.10849 0 -0.0013306"
      rpy="0.00018456 -0.00018462 0.00026345" />
    <parent
      link="rear_right_femur_link" />
    <child
      link="rear_right_tibia_link" />
    <axis
      xyz="0 -1 0" />
    <limit
      lower="0"
      upper="3.1415"
      effort="0"
      velocity="0" />
  </joint>
  <link
    name="rear_right_foot_link">
    <inertial>
      <origin
        xyz="-1.1436E-09 7.9452E-11 -0.00013914"
        rpy="0 0 0" />
      <mass
        value="0.0010269" />
      <inertia
        ixx="1.6656E-08"
        ixy="4.2207E-15"
        ixz="5.7554E-15"
        iyy="1.6656E-08"
        iyz="-3.9949E-16"
        izz="1.7246E-08" />
    </inertial>
    <visual>
      <origin
        xyz="0 0 0"
        rpy="0 0 0" />
      <geometry>
        <mesh
          filename="package://robot_description/meshes/rear_right_foot_link.STL" />
      </geometry>
      <material
        name="">
        <color
          rgba="1 1 1 1" />
      </material>
    </visual>
    <collision>
      <origin
        xyz="0 0 0"
        rpy="0 0 0" />
      <geometry>
        <mesh
          filename="package://robot_description/meshes/rear_right_foot_link.STL" />
      </geometry>
    </collision>
  </link>
  <joint
    name="rear_right_foot_joint"
    type="fixed">
    <origin
      xyz="-0.157028654923349 -0.000166190898619894 0.0381859537813168"
      rpy="2.27118164194299 0.422454157208764 1.9033120345656" />
    <parent
      link="rear_right_tibia_link" />
    <child
      link="rear_right_foot_link" />
    <axis
      xyz="0 0 0" />
  </joint>
</robot>